Workbook

Sheet Priority list
A1: LibreCarve priority list: features rivals have that LibreCarve lacks
A2: Rule: items 1-3 gate the alpha. After that, order by how many of the 8 rival products have the feature (Yes = 1, Partial = 0.5), then by plan phase. Blue cells are for you to edit. Source of status: the Matrix sheet.
A4: # | B4: Item | C4: LibreCarve now | D4: Rivals with it (of 8) | E4: Plan phase | F4: Work status | G4: Notes
A5: 1 | B5: Real cut on the Onefinity Woodworker in MDF; confirm the T1 and M0 prompts on the controller | C5: Alpha gate | D5: - | E5: 0 | F5: Done | G5: Real cut done 2026-10-16 on the Onefinity. The bit-change (T1/M0) height was too low; it is now a setting (variable), so the condition is cleared.
A6: 2 | B6: Find out whether the 48 Verify violations in the demo job (of 360,957 points) are real gouges | C6: Alpha gate | D6: - | E6: 0 | F6: Done | G6: The violations were real gouges, fixed by #57; the demo job now verifies with 0 violations and has a regression test (PR #111).
A7: 3 | B7: An installable build and a way for testers to report problems | C7: Alpha gate | D7: - | E7: 0 | F7: Done | G7: PR #108 merged 2026-10-16: Linux release workflow, installer, issue forms, INSTALL.md. Fully done after the first tagged release (v0.1.2) builds.
A8: 92 | B8: Relief jobs must look like the carve: the canvas and the SVG, PNG and PDF exports show the shaded relief (the simulated result), not a mess of scan lines | C8: Done | D8: - | E8: Usability | F8: Done | G8: Done. Merged in PR #186 (2026-10-22): the canvas and the SVG, PNG and PDF exports show the shaded relief; scan lines are hidden unless Show path is ticked. Reviewed: canvas and PNG export look like the carve. Stale help lines corrected; help page now explains the three stages of the picture (PR #189).
A9: 93 | B9: Relief toolpaths must pass Verify: the finish and rough passes of a picture relief fail by up to 0.0016 inch, so no G-code can be posted | C9: Done | D9: - | E9: Safety | F9: Done | G9: Done. Merged in PR #185 (2026-10-22). Cause: the generated path used cell heights at sampled points while the checker read the surface between them. Fixed by clearing the cell heights between sampled points; the checker was not loosened. Checked on the owner's machine 2026-10-22: the Desert job (rough + 60 degree V-bit finish) verifies with 1,478,216 points checked and 0 violations.
A10: 94 | B10: The canvas render of a relief must look like the carve (shaded, like the Simulation top view), live, with scan lines hidden unless chosen | C10: Done | D10: - | E10: Usability | F10: Done | G10: Done. Merged with item 92 in PR #186. Pass met: on the Desert job the canvas reads as the carved picture, and the owner confirmed it looks right (2026-10-22). The picture changes as the job grows (height map, then rough simulation, then finish simulation); documented in PR #189.
A11: 95 | B11: Automatic depth mapping and one-step photo carving: auto tone, trim, depth fit to the stock, a Photo to relief recipe (rough + finish + verify + simulate), then AI depth from an ordinary photo (local ONNX model, Depth Anything V2 Small) | C11: Partial | D11: - | E11: Usability | F11: In progress | G11: Owner request 2026-10-21 after hand-building the Desert carve. Stage A merged in PR #187 (2026-10-22): tone "auto", border trim, depth "fit", job.photo recipe and the Photo to Relief form; it never posts. Now verifies cleanly since PR #185. Stage B (AI depth from an ordinary photo) is NOT started: local depth model via ort (MIT/Apache), model not committed, explicit download, Depth Anything V2 Small only (Apache-2.0; Base and Large are non-commercial). Corner watermarks still need an explicit crop (not automatic). Stays In progress until Stage B.
A12: 88 | B12: Show the material in the design window, with the zero point marked, so a design can be placed on it | C12: Not started | D12: - | E12: Usability | F12: Done | G12: PR #174 merged 2026-10-19: stock rectangle and zero-point marker drawn in the design window.
A13: 89 | B13: Job setup first: material size, thickness and the zero point (a material corner, the centre, or the spoilboard) | C13: Partial | D13: - | E13: Usability | F13: Done | G13: PR #174 merged 2026-10-19: Material Setup entry, spoilboard zero, palette buttons disabled with no material.
A14: 90 | B14: Import a complex drawing as one grouped object, so it resizes as one; ungroup to edit | C14: Not started | D14: - | E14: Usability | F14: Done | G14: PR #172 merged 2026-10-19: grouped import on by default (group:false turns it off); resize as one, Ungroup to edit; locked groups and hostile input guarded.
A15: 91 | B15: 3D simulation view: zoom with the mouse wheel (and pan) | C15: Not started | D15: - | E15: Usability | F15: Done | G15: PR #173 merged 2026-10-19: wheel and pinch zoom, middle/right/Shift drag pan in the 3D simulation view.
A16: 4 | B16: =Matrix!A68 -> Machine profiles and setup wizard | C16: =Matrix!C68 -> Partial | D16: =COUNTIF(Matrix!D68:K68,"Yes")+0.5*COUNTIF(Matrix!D68:K68,"Partial") -> 7 | E16: Not set | F16: Done | G16: Machine Setup window, profiles, limit checks and Onefinity models are built. Homing, soft limits, steps per mm and probe calibration are out of scope on purpose (they stay on the machine's controller). PR #132 merged 2026-10-16 after an Opus review and a rebase over multi-sheet: six-step Machine Setup Wizard (Toolpaths menu, Machine Setup window, first-run prompt) and cam.machine.wizard for agents; saves through cam.machine; profiles gain safe_z and bit_change_z. Opus-reviewed. Left: translations, default the first step to the job machine when it came from an unsaved preset.
A17: 5 | B17: =Matrix!A66 -> Post-processor library | C17: =Matrix!C66 -> Partial | D17: =COUNTIF(Matrix!D66:K66,"Yes")+0.5*COUNTIF(Matrix!D66:K66,"Partial") -> 7 | E17: 1 | F17: Done | G17: PR #109 merged 2026-10-16: data-driven post library (onefinity, grbl, grbl-manual, linuxcnc, mach, marlin, generic), unsafe definitions refused, Opus-reviewed. Not yet run on a real controller other than the Onefinity.
A18: 6 | B18: =Matrix!A55 -> 3D roughing and finishing of a model | C18: =Matrix!C55 -> Planned | D18: =COUNTIF(Matrix!D55:K55,"Yes")+0.5*COUNTIF(Matrix!D55:K55,"Partial") -> 6 | E18: 1 | F18: In progress | G18: PR #126 merged 2026-10-16: z_level roughing, offset finishing, independent gouge checker, rough default-pass bug fixed, finish stepover reported correctly. Still missing: multi-tool rest finishing, depth-first roughing, projecting 2D toolpaths onto the surface.
A19: 7 | B19: =Matrix!A10 -> Node editing and Bezier curves | C19: =Matrix!C10 -> Partial | D19: =COUNTIF(Matrix!D10:K10,"Yes")+0.5*COUNTIF(Matrix!D10:K10,"Partial") -> 6 | E19: 1 | F19: Done | G19: PR #127 merged 2026-10-16: node editing mode, Bezier tool, node.* commands, new librecarve-nodes crate, Opus-reviewed. Left: bend a span by dragging, join open ends, translations.
A20: 8 | B20: =Matrix!A27 -> STL, OBJ and 3MF mesh import | C20: =Matrix!C27 -> Partial | D20: =COUNTIF(Matrix!D27:K27,"Yes")+0.5*COUNTIF(Matrix!D27:K27,"Partial") -> 6 | E20: 1 | F20: In progress | G20: Imports as a height map and embeds in the stock; an Import 3D Model window is in review
A21: 9 | B21: =Matrix!A43 -> Pocket extras: raster clearing, wall finish, fewer retracts | C21: =Matrix!C43 -> Planned | D21: =COUNTIF(Matrix!D43:K43,"Yes")+0.5*COUNTIF(Matrix!D43:K43,"Partial") -> 5.5 | E21: 1 | F21: Done | G21: PR #124 merged 2026-10-16: raster clearing, wall finish pass, fewer retracts (all off by default), Opus-reviewed. Left: helical entry, a cap on large finish stock.
A22: 10 | B22: =Matrix!A35 -> Rotary (4th axis) wrapping | C22: =Matrix!C35 -> Planned | D22: =COUNTIF(Matrix!D35:K35,"Yes")+0.5*COUNTIF(Matrix!D35:K35,"Partial") -> 4.5 | E22: 1 | F22: In progress | G22: Paused, work in a worktree, no PR yet.
A23: 11 | B23: =Matrix!A33 -> Several sheets or setups in one job | C23: =Matrix!C33 -> Planned | D23: =COUNTIF(Matrix!D33:K33,"Yes")+0.5*COUNTIF(Matrix!D33:K33,"Partial") -> 5 | E23: 1 | F23: Done | G23: PR #125 merged 2026-10-16: several sheets per job (cam.setup.*), per-sheet verify, simulate and G-code with a safe sheet change, rebased over the post library and Opus-reviewed. Left: assign shapes to sheets automatically, nesting, copy a sheet with its toolpaths.
A24: 12 | B24: =Matrix!A51 -> Chamfer and countersink toolpaths | C24: =Matrix!C51 -> Planned | D24: =COUNTIF(Matrix!D51:K51,"Yes")+0.5*COUNTIF(Matrix!D51:K51,"Partial") -> 5 | E24: 2 | F24: Done | G24: Merged (PR 151) after Opus review, fix: ring countersink move cap. Library now 47 tools. Open: climb direction convention may be reversed in all strategies (needs decision); not cut on a real machine.
A25: 13 | B25: =Matrix!A45 -> Thread milling | C25: =Matrix!C45 -> Planned | D25: =COUNTIF(Matrix!D45:K45,"Yes")+0.5*COUNTIF(Matrix!D45:K45,"Partial") -> 5 | E25: 2 | F25: Done | G25: Merged (PR 152) after Opus review, 2 fixes (sub-pitch thread coverage, verify floor). Open: feed is at tool center so the cutting edge runs faster in small holes; not tested on a real machine.
A26: 14 | B26: =Matrix!A20 -> Image tracing to vectors (form and button done; wasm picture picker still to do) | C26: =Matrix!C20 -> Done | D26: =COUNTIF(Matrix!D20:K20,"Yes")+0.5*COUNTIF(Matrix!D20:K20,"Partial") -> 5.5 | E26: 1 | F26: Done | G26: Trace picture form and button landed (item 14, commit b0d4f63). The wasm picture picker is still to do.
A27: 15 | B27: =Matrix!A34 -> Two-sided jobs with a flip | C27: =Matrix!C34 -> Partial | D27: =COUNTIF(Matrix!D34:K34,"Yes")+0.5*COUNTIF(Matrix!D34:K34,"Partial") -> 4.5 | E27: 1 | F27: Done | G27: Merged (PR 150) after Opus review. Fixes: verify grid for large stock, hatch/raster angle mirror, thread and countersink hole mirror, unsafe spoilboard warning. Open: pause does not name the sheet, one-plunge pin holes; not cut on a real machine.
A28: 16 | B28: =Matrix!A74 -> Toolpath templates, merged toolpaths, setup sheets | C28: =Matrix!C74 -> Planned | D28: =COUNTIF(Matrix!D74:K74,"Yes")+0.5*COUNTIF(Matrix!D74:K74,"Partial") -> 4.5 | E28: 2 | F28: In progress | G28: Built in a worktree, no PR yet.
A29: 17 | B29: =Matrix!A52 -> True-shape nesting | C29: =Matrix!C52 -> Planned | D29: =COUNTIF(Matrix!D52:K52,"Yes")+0.5*COUNTIF(Matrix!D52:K52,"Partial") -> 4.5 | E29: 2 | F29: Done | G29: Merged (PR 149); reviewed, 4 fixes (time limit, memory guard, setup limit).
A30: 18 | B30: =Matrix!A48 -> V-carve flat bottom with a second tool | C30: =Matrix!C48 -> Partial | D30: =COUNTIF(Matrix!D48:K48,"Yes")+0.5*COUNTIF(Matrix!D48:K48,"Partial") -> 3.5 | E30: 1 | F30: In progress | G30: Flat bottom with a second tool is built; still to do: several passes, start points, joined runs, smoothing, auto-weld
A31: 19 | B31: =Matrix!A49 -> Inlay (plug and pocket that fit) | C31: =Matrix!C49 -> Planned | D31: =COUNTIF(Matrix!D49:K49,"Yes")+0.5*COUNTIF(Matrix!D49:K49,"Partial") -> 3.5 | E31: 2 | F31: Not started
A32: 20 | B32: =Matrix!A28 -> STEP and IGES import | C32: =Matrix!C28 -> Planned | D32: =COUNTIF(Matrix!D28:K28,"Yes")+0.5*COUNTIF(Matrix!D28:K28,"Partial") -> 3 | E32: 4 | F32: Not started
A33: 21 | B33: =Matrix!A21 -> Bitmap tools: brightness, contrast, crop | C33: =Matrix!C21 -> Partial | D33: =COUNTIF(Matrix!D21:K21,"Yes")+0.5*COUNTIF(Matrix!D21:K21,"Partial") -> 2.5 | E33: 1 | F33: Done | G33: Merged (PR 155), written by Nemotron, Opus review found 5 bugs and missing tests, all fixed. Brightness, contrast, gamma, crop, rotate, flip before trace. Open: form uses number fields, not sliders.
A34: 22 | B34: =Matrix!A26 -> EPS, AI and PDF import | C34: =Matrix!C26 -> Planned | D34: =COUNTIF(Matrix!D26:K26,"Yes")+0.5*COUNTIF(Matrix!D26:K26,"Partial") -> 2.5 | E34: 1 | F34: Done | G34: PR 147 open, in review. Tester report fixed: large SVG no longer refused ("path has too many segments"), PR 148 merged after Opus review (2 fixes: corner accuracy, join order). PDF, AI and EPS import merged (PR 147), Opus review fixed compound paths, curve operators, page size, memory blowups and a panic. Unicode-3.0 license approved. Open: EPS from Inkscape/cairo (short procedure names) imports nothing; PDF form XObjects skipped with a warning.
A35: 23 | B35: =Matrix!A69 -> Send to the machine from inside the program | C35: =Matrix!C69 -> Partial | D35: =COUNTIF(Matrix!D69:K69,"Yes")+0.5*COUNTIF(Matrix!D69:K69,"Partial") -> 2.5 | E35: 1 | F35: Conditionally approved | G35: PR #135 merged 2026-10-16 after an Opus safety review: Onefinity file upload (never starts the job) and GRBL serial streaming, Send to Machine window with three confirmations, verify required on every sheet, agents can only dry-run. Tested against fakes only. Done after a real air cut: confirm which upload address the Onefinity firmware accepts, and the GRBL pause and Continue.
A36: 24 | B36: =Matrix!A76 -> Cabinet workflow: labels, drill banks, cabinet import | C36: =Matrix!C76 -> Planned | D36: =COUNTIF(Matrix!D76:K76,"Yes")+0.5*COUNTIF(Matrix!D76:K76,"Partial") -> 2.5 | E36: 2 | F36: Not started
A37: 25 | B37: =Matrix!A19 -> Text on a curve, kerning, spell check | C37: =Matrix!C19 -> Partial | D37: =COUNTIF(Matrix!D19:K19,"Yes")+0.5*COUNTIF(Matrix!D19:K19,"Partial") -> 2 | E37: 1 | F37: In progress | G37: Text on a curve and kerning merged (PR #144, 31 tests). Still to do: spell check.
A38: 45 | B38: =Matrix!A89 -> Multi-tool rest clearing | C38: =Matrix!C89 -> Planned | D38: =COUNTIF(Matrix!D89:K89,"Yes")+0.5*COUNTIF(Matrix!D89:K89,"Partial") -> 2 | E38: 1c | F38: Done | G38: PR #164 merged 2026-10-19: stacked V-carve with per-tool pass depth and stepover winning over the global values.
A39: 26 | B39: =Matrix!A50 -> Fluting, texture, raised prism, moulding | C39: =Matrix!C50 -> Planned | D39: =COUNTIF(Matrix!D50:K50,"Yes")+0.5*COUNTIF(Matrix!D50:K50,"Partial") -> 2 | E39: 2 | F39: Not started
A40: 27 | B40: =Matrix!A75 -> Laser output and hybrid CNC/laser jobs | C40: =Matrix!C75 -> Planned | D40: =COUNTIF(Matrix!D75:K75,"Yes")+0.5*COUNTIF(Matrix!D75:K75,"Partial") -> 1.5 | E40: 4 | F40: Not started
A41: 28 | B41: =Matrix!A56 -> Relief modelling: components, shapes, sculpting (Aspire) | C41: =Matrix!C56 -> Planned | D41: =COUNTIF(Matrix!D56:K56,"Yes")+0.5*COUNTIF(Matrix!D56:K56,"Partial") -> 1.5 | E41: 3 | F41: Not started
...

Sheet Differentiators
A1: Differentiators: things LibreCarve does that rivals do not
A2: Not ranked by rival count. Status uses the same values as the Priority list.
A4: # | B4: Differentiator | C4: Work status | D4: Why it sets LibreCarve apart | E4: Priority list item
A5: D1 | B5: AI-driven jobs with Claude: the model runs the whole job through MCP or the shell helper | C5: Done | D5: Rivals have no scripting or agent control. Tested complete with Claude.
A6: D2 | B6: Texture Design: height maps generated from parameters, usable by command | C6: In progress | D6: Textures and relief come from commands, so they can be scripted and repeated.
A7: D3 | B7: No edition limits | C7: Done | D7: No work-area, model-count or toolpath-size caps and no paid tiers.
A8: D4 | B8: Cross-platform and web builds | C8: In progress | D8: Same core runs native on Linux, Windows, macOS and in the browser (wasm).
A9: D5 | B9: Local AI support: a local model (Qwen 27B in the Deepseek harness) runs a whole job | C9: Done | D9: Same control, no cloud: the job stays on the shop machine. | E9: 84

Sheet Matrix
A1: LibreCarve vs the CNC software field: features by product, cheapest to dearest
A2: LibreCarve column = status in the repo on 2026-10-15. Other columns: Yes / Partial / No / ? (not confirmed). Products run left to right from free to the highest cost.
A4: Feature | B4: Plan phase | C4: LibreCarve (status) | D4: FreeCAD | E4: Carbide Create Pro | F4: Easel | G4: Easel Pro | H4: Fusion 360 | I4: VCarve Pro | J4: Aspire | K4: Mastercam | L4: Rivals with it (of 8): Yes = 1, Partial = 0.5 | M4: Build priority rank (1 = first)
A5: Price / licence | C5: Free, open source | D5: Free, open source | E5: $120/year subscription, or $360 once | F5: Free plan: $0, 1 export per week (Starter $72/year adds 20 per week) | G5: $216/year ($72 Starter; Free tier: 1 export/week) | H5: $680/year (free for non-commercial personal use) | I5: $699 once (perpetual) | J5: $1,995 once (perpetual) | K5: No public price; est. $6,000-$15,000 perpetual + maintenance
A6: First-year cost (USD, number) | C6: 0 | D6: 0 | E6: 120 | F6: 0 | G6: 216 | H6: 680 | I6: 699 | J6: 1995 | K6: 6000
A7: Price source | E7: Carbide 3D buy page, Oct 2026 | F7: Easel plans page (support.easel.com), read Oct 2026. Rows the page does not cover are ? | G7: Easel plans page, Oct 2026 | H7: Vagon pricing summary, checked Aug 2026 | I7: Retailer listing (Onefinity CNC), Oct 2026 | J7: Retailer listing, Oct 2026 | K7: ESTIMATE: NexGen comparison page; 2017 forum post said $5,000/year for 3-axis
A8: 1. 2D design and drawing
A9: Shapes: line, arc, circle, rectangle, polygon, polyline | B9: Built | C9: Done | D9: Yes | E9: Yes | F9: No | G9: Yes | H9: Yes | I9: Yes | J9: Yes | K9: Yes | L9: =IF(COUNTIF(D9:K9,"?")=8,"n/a",COUNTIF(D9:K9,"Yes")+0.5*COUNTIF(D9:K9,"Partial")) -> 7 | M9: =IFERROR(INDEX('Priority list'!$A$5:$A$200,MATCH(A9,'Priority list'!$B$5:$B$200,0)),IF(C9="Done","Done","-")) -> Done
A10: Node editing and Bezier curves | B10: 1 | C10: Partial | D10: Yes | E10: Yes | F10: No | G10: No | H10: Yes | I10: Yes | J10: Yes | K10: Yes | L10: =IF(COUNTIF(D10:K10,"?")=8,"n/a",COUNTIF(D10:K10,"Yes")+0.5*COUNTIF(D10:K10,"Partial")) -> 6 | M10: =IFERROR(INDEX('Priority list'!$A$5:$A$200,MATCH(A10,'Priority list'!$B$5:$B$200,0)),IF(C10="Done","Done","-")) -> 7
A11: Offset, trim, fillet, mirror, move, scale | B11: Built | C11: Done | D11: Yes | E11: Partial | F11: ? | G11: Partial | H11: Yes | I11: Yes | J11: Yes | K11: Yes | L11: =IF(COUNTIF(D11:K11,"?")=8,"n/a",COUNTIF(D11:K11,"Yes")+0.5*COUNTIF(D11:K11,"Partial")) -> 6 | M11: =IFERROR(INDEX('Priority list'!$A$5:$A$200,MATCH(A11,'Priority list'!$B$5:$B$200,0)),IF(C11="Done","Done","-")) -> Done
A12: Rectangular and circular arrays | B12: Built | C12: Done | D12: Yes | E12: Yes | F12: No | G12: No | H12: Yes | I12: Yes | J12: Yes | K12: Yes | L12: =IF(COUNTIF(D12:K12,"?")=8,"n/a",COUNTIF(D12:K12,"Yes")+0.5*COUNTIF(D12:K12,"Partial")) -> 6 | M12: =IFERROR(INDEX('Priority list'!$A$5:$A$200,MATCH(A12,'Priority list'!$B$5:$B$200,0)),IF(C12="Done","Done","-")) -> Done
A13: Dimensions that update with the part | B13: Built | C13: Done | D13: Yes | E13: No | F13: No | G13: No | H13: Yes | I13: Partial | J13: Partial | K13: Yes | L13: =IF(COUNTIF(D13:K13,"?")=8,"n/a",COUNTIF(D13:K13,"Yes")+0.5*COUNTIF(D13:K13,"Partial")) -> 4 | M13: =IFERROR(INDEX('Priority list'!$A$5:$A$200,MATCH(A13,'Priority list'!$B$5:$B$200,0)),IF(C13="Done","Done","-")) -> Done
A14: Booleans: weld, subtract, intersect | B14: Built | C14: Done | D14: Yes | E14: Yes | F14: ? | G14: Yes | H14: Yes | I14: Yes | J14: Yes | K14: Yes | L14: =IF(COUNTIF(D14:K14,"?")=8,"n/a",COUNTIF(D14:K14,"Yes")+0.5*COUNTIF(D14:K14,"Partial")) -> 7 | M14: =IFERROR(INDEX('Priority list'!$A$5:$A$200,MATCH(A14,'Priority list'!$B$5:$B$200,0)),IF(C14="Done","Done","-")) -> Done
A15: Shape check and tidy (gaps, duplicates, overlaps) | B15: Built | C15: Done | D15: Partial | E15: Partial | F15: No | G15: No | H15: Partial | I15: Yes | J15: Yes | K15: Yes | L15: =IF(COUNTIF(D15:K15,"?")=8,"n/a",COUNTIF(D15:K15,"Yes")+0.5*COUNTIF(D15:K15,"Partial")) -> 4.5 | M15: =IFERROR(INDEX('Priority list'!$A$5:$A$200,MATCH(A15,'Priority list'!$B$5:$B$200,0)),IF(C15="Done","Done","-")) -> Done
A16: 2. Text and bitmaps
A17: TrueType and OpenType text to cuttable outlines | B17: Built | C17: Done | D17: Yes | E17: Yes | F17: Partial | G17: Yes | H17: Yes | I17: Yes | J17: Yes | K17: Yes | L17: =IF(COUNTIF(D17:K17,"?")=8,"n/a",COUNTIF(D17:K17,"Yes")+0.5*COUNTIF(D17:K17,"Partial")) -> 7.5 | M17: =IFERROR(INDEX('Priority list'!$A$5:$A$200,MATCH(A17,'Priority list'!$B$5:$B$200,0)),IF(C17="Done","Done","-")) -> Done
A18: Starter font set shipped, and importing your own fonts | B18: Built | C18: Done | D18: ? | E18: ? | F18: ? | G18: ? | H18: ? | I18: ? | J18: ? | K18: ? | L18: =IF(COUNTIF(D18:K18,"?")=8,"n/a",COUNTIF(D18:K18,"Yes")+0.5*COUNTIF(D18:K18,"Partial")) -> n/a | M18: =IFERROR(INDEX('Priority list'!$A$5:$A$200,MATCH(A18,'Priority list'!$B$5:$B$200,0)),IF(C18="Done","Done","-")) -> Done
A19: Text on a curve, kerning, spell check | B19: 1 | C19: Partial | D19: No | E19: ? | F19: No | G19: No | H19: No | I19: Yes | J19: Yes | K19: ? | L19: =IF(COUNTIF(D19:K19,"?")=8,"n/a",COUNTIF(D19:K19,"Yes")+0.5*COUNTIF(D19:K19,"Partial")) -> 2 | M19: =IFERROR(INDEX('Priority list'!$A$5:$A$200,MATCH(A19,'Priority list'!$B$5:$B$200,0)),IF(C19="Done","Done","-")) -> 25
A20: Image tracing to vectors (form and button done; wasm picture picker still to do) | B20: 1 | C20: Done | D20: Partial | E20: Yes | F20: Yes | G20: Yes | H20: No | I20: Yes | J20: Yes | K20: No | L20: =IF(COUNTIF(D20:K20,"?")=8,"n/a",COUNTIF(D20:K20,"Yes")+0.5*COUNTIF(D20:K20,"Partial")) -> 5.5 | M20: =IFERROR(INDEX('Priority list'!$A$5:$A$200,MATCH(A20,'Priority list'!$B$5:$B$200,0)),IF(C20="Done","Done","-")) -> 14
A21: Bitmap tools: brightness, contrast, crop | B21: 1 | C21: Partial | D21: No | E21: Partial | F21: No | G21: No | H21: No | I21: Yes | J21: Yes | K21: No | L21: =IF(COUNTIF(D21:K21,"?")=8,"n/a",COUNTIF(D21:K21,"Yes")+0.5*COUNTIF(D21:K21,"Partial")) -> 2.5 | M21: =IFERROR(INDEX('Priority list'!$A$5:$A$200,MATCH(A21,'Priority list'!$B$5:$B$200,0)),IF(C21="Done","Done","-")) -> 21
A22: 3. Import and export
A23: DXF import | B23: Built | C23: Done | D23: Yes | E23: Yes | F23: ? | G23: Yes | H23: Yes | I23: Yes | J23: Yes | K23: Yes | L23: =IF(COUNTIF(D23:K23,"?")=8,"n/a",COUNTIF(D23:K23,"Yes")+0.5*COUNTIF(D23:K23,"Partial")) -> 7 | M23: =IFERROR(INDEX('Priority list'!$A$5:$A$200,MATCH(A23,'Priority list'!$B$5:$B$200,0)),IF(C23="Done","Done","-")) -> Done
A24: SVG import | B24: Built | C24: Done | D24: Yes | E24: Yes | F24: Yes | G24: Yes | H24: Yes | I24: Yes | J24: Yes | K24: ? | L24: =IF(COUNTIF(D24:K24,"?")=8,"n/a",COUNTIF(D24:K24,"Yes")+0.5*COUNTIF(D24:K24,"Partial")) -> 7 | M24: =IFERROR(INDEX('Priority list'!$A$5:$A$200,MATCH(A24,'Priority list'!$B$5:$B$200,0)),IF(C24="Done","Done","-")) -> Done
A25: DWG import | B25: Built | C25: Done | D25: Partial | E25: No | F25: No | G25: No | H25: Yes | I25: ? | J25: ? | K25: Yes | L25: =IF(COUNTIF(D25:K25,"?")=8,"n/a",COUNTIF(D25:K25,"Yes")+0.5*COUNTIF(D25:K25,"Partial")) -> 2.5 | M25: =IFERROR(INDEX('Priority list'!$A$5:$A$200,MATCH(A25,'Priority list'!$B$5:$B$200,0)),IF(C25="Done","Done","-")) -> Done
A26: EPS, AI and PDF import | B26: 1 | C26: Planned | D26: Partial | E26: ? | F26: No | G26: No | H26: No | I26: Yes | J26: Yes | K26: ? | L26: =IF(COUNTIF(D26:K26,"?")=8,"n/a",COUNTIF(D26:K26,"Yes")+0.5*COUNTIF(D26:K26,"Partial")) -> 2.5 | M26: =IFERROR(INDEX('Priority list'!$A$5:$A$200,MATCH(A26,'Priority list'!$B$5:$B$200,0)),IF(C26="Done","Done","-")) -> 22
A27: STL, OBJ and 3MF mesh import | B27: 1 | C27: Partial | D27: Yes | E27: Yes | F27: No | G27: No | H27: Yes | I27: Yes | J27: Yes | K27: Yes | L27: =IF(COUNTIF(D27:K27,"?")=8,"n/a",COUNTIF(D27:K27,"Yes")+0.5*COUNTIF(D27:K27,"Partial")) -> 6 | M27: =IFERROR(INDEX('Priority list'!$A$5:$A$200,MATCH(A27,'Priority list'!$B$5:$B$200,0)),IF(C27="Done","Done","-")) -> 8
A28: STEP and IGES import | B28: 4 | C28: Planned | D28: Yes | E28: No | F28: No | G28: No | H28: Yes | I28: No | J28: No | K28: Yes | L28: =IF(COUNTIF(D28:K28,"?")=8,"n/a",COUNTIF(D28:K28,"Yes")+0.5*COUNTIF(D28:K28,"Partial")) -> 3 | M28: =IFERROR(INDEX('Priority list'!$A$5:$A$200,MATCH(A28,'Priority list'!$B$5:$B$200,0)),IF(C28="Done","Done","-")) -> 20
A29: DXF export of vectors | B29: Built | C29: Done | D29: Yes | E29: Yes | F29: No | G29: No | H29: Yes | I29: Yes | J29: Yes | K29: Yes | L29: =IF(COUNTIF(D29:K29,"?")=8,"n/a",COUNTIF(D29:K29,"Yes")+0.5*COUNTIF(D29:K29,"Partial")) -> 6 | M29: =IFERROR(INDEX('Priority list'!$A$5:$A$200,MATCH(A29,'Priority list'!$B$5:$B$200,0)),IF(C29="Done","Done","-")) -> Done
A30: 4. Job setup
A31: Stock size, Z zero, safe Z, XY datum, metric and inch | B31: Built | C31: Done | D31: Yes | E31: Yes | F31: Partial | G31: Yes | H31: Yes | I31: Yes | J31: Yes | K31: Yes | L31: =IF(COUNTIF(D31:K31,"?")=8,"n/a",COUNTIF(D31:K31,"Yes")+0.5*COUNTIF(D31:K31,"Partial")) -> 7.5 | M31: =IFERROR(INDEX('Priority list'!$A$5:$A$200,MATCH(A31,'Priority list'!$B$5:$B$200,0)),IF(C31="Done","Done","-")) -> Done
A32: Project files, layers, saved job recipes | B32: Built | C32: Done | D32: Yes | E32: Yes | F32: Partial | G32: Partial | H32: Yes | I32: Yes | J32: Yes | K32: Yes | L32: =IF(COUNTIF(D32:K32,"?")=8,"n/a",COUNTIF(D32:K32,"Yes")+0.5*COUNTIF(D32:K32,"Partial")) -> 7 | M32: =IFERROR(INDEX('Priority list'!$A$5:$A$200,MATCH(A32,'Priority list'!$B$5:$B$200,0)),IF(C32="Done","Done","-")) -> Done
A33: Several sheets or setups in one job | B33: 1 | C33: Planned | D33: Yes | E33: No | F33: No | G33: No | H33: Yes | I33: Yes | J33: Yes | K33: Yes | L33: =IF(COUNTIF(D33:K33,"?")=8,"n/a",COUNTIF(D33:K33,"Yes")+0.5*COUNTIF(D33:K33,"Partial")) -> 5 | M33: =IFERROR(INDEX('Priority list'!$A$5:$A$200,MATCH(A33,'Priority list'!$B$5:$B$200,0)),IF(C33="Done","Done","-")) -> 11
A34: Two-sided jobs with a flip | B34: 1 | C34: Partial | D34: Partial | E34: ? | F34: No | G34: No | H34: Yes | I34: Yes | J34: Yes | K34: Yes | L34: =IF(COUNTIF(D34:K34,"?")=8,"n/a",COUNTIF(D34:K34,"Yes")+0.5*COUNTIF(D34:K34,"Partial")) -> 4.5 | M34: =IFERROR(INDEX('Priority list'!$A$5:$A$200,MATCH(A34,'Priority list'!$B$5:$B$200,0)),IF(C34="Done","Done","-")) -> 15
A35: Rotary (4th axis) wrapping | B35: 1 | C35: Planned | D35: Partial | E35: ? | F35: No | G35: No | H35: Yes | I35: Yes | J35: Yes | K35: Yes | L35: =IF(COUNTIF(D35:K35,"?")=8,"n/a",COUNTIF(D35:K35,"Yes")+0.5*COUNTIF(D35:K35,"Partial")) -> 4.5 | M35: =IFERROR(INDEX('Priority list'!$A$5:$A$200,MATCH(A35,'Priority list'!$B$5:$B$200,0)),IF(C35="Done","Done","-")) -> 10
A36: Hold-down setting with a warning on through cuts | B36: Built | C36: Done | D36: No | E36: ? | F36: No | G36: No | H36: No | I36: ? | J36: ? | K36: No | L36: =IF(COUNTIF(D36:K36,"?")=8,"n/a",COUNTIF(D36:K36,"Yes")+0.5*COUNTIF(D36:K36,"Partial")) -> 0 | M36: =IFERROR(INDEX('Priority list'!$A$5:$A$200,MATCH(A36,'Priority list'!$B$5:$B$200,0)),IF(C36="Done","Done","-")) -> Done
A37: 5. 2D and 2.5D toolpaths
A38: Profile: inside, outside, on the line | B38: Built | C38: Done | D38: Yes | E38: Yes | F38: Yes | G38: Yes | H38: Yes | I38: Yes | J38: Yes | K38: Yes | L38: =IF(COUNTIF(D38:K38,"?")=8,"n/a",COUNTIF(D38:K38,"Yes")+0.5*COUNTIF(D38:K38,"Partial")) -> 8 | M38: =IFERROR(INDEX('Priority list'!$A$5:$A$200,MATCH(A38,'Priority list'!$B$5:$B$200,0)),IF(C38="Done","Done","-")) -> Done
A39: Holding tabs | B39: Built | C39: Done | D39: Yes | E39: Yes | F39: ? | G39: Yes | H39: Yes | I39: Yes | J39: Yes | K39: Yes | L39: =IF(COUNTIF(D39:K39,"?")=8,"n/a",COUNTIF(D39:K39,"Yes")+0.5*COUNTIF(D39:K39,"Partial")) -> 7 | M39: =IFERROR(INDEX('Priority list'!$A$5:$A$200,MATCH(A39,'Priority list'!$B$5:$B$200,0)),IF(C39="Done","Done","-")) -> Done
A40: Ramp entry and lead-in/out | B40: Built | C40: Done | D40: Yes | E40: Partial | F40: No | G40: No | H40: Yes | I40: Yes | J40: Yes | K40: Yes | L40: =IF(COUNTIF(D40:K40,"?")=8,"n/a",COUNTIF(D40:K40,"Yes")+0.5*COUNTIF(D40:K40,"Partial")) -> 5.5 | M40: =IFERROR(INDEX('Priority list'!$A$5:$A$200,MATCH(A40,'Priority list'!$B$5:$B$200,0)),IF(C40="Done","Done","-")) -> Done
A41: Pocket with islands | B41: Built | C41: Done | D41: Yes | E41: Yes | F41: ? | G41: Yes | H41: Yes | I41: Yes | J41: Yes | K41: Yes | L41: =IF(COUNTIF(D41:K41,"?")=8,"n/a",COUNTIF(D41:K41,"Yes")+0.5*COUNTIF(D41:K41,"Partial")) -> 7 | M41: =IFERROR(INDEX('Priority list'!$A$5:$A$200,MATCH(A41,'Priority list'!$B$5:$B$200,0)),IF(C41="Done","Done","-")) -> Done
...

Sheet Summary
A1: Counts from the Matrix sheet (formulas)
A3: Product | B3: Done / Yes | C3: Partial | D3: Planned | E3: No / Not planned | F3: ? (unconfirmed) | G3: Score: (Yes + half of Partial) / rated rows
A4: LibreCarve | B4: =COUNTIF(Matrix!C8:C77,"Done")+COUNTIF(Matrix!C8:C77,"Yes") -> 34 | C4: =COUNTIF(Matrix!C8:C77,"Partial") -> 10 | D4: =COUNTIF(Matrix!C8:C77,"Planned") -> 15 | E4: =COUNTIF(Matrix!C8:C77,"No")+COUNTIF(Matrix!C8:C77,"Not planned") -> 3 | F4: =COUNTIF(Matrix!C8:C77,"?") -> 0 | G4: =IFERROR((B4+0.5*C4)/(B4+C4+D4+E4),0) -> 0.62903226
A5: FreeCAD | B5: =COUNTIF(Matrix!D8:D77,"Done")+COUNTIF(Matrix!D8:D77,"Yes") -> 32 | C5: =COUNTIF(Matrix!D8:D77,"Partial") -> 13 | D5: =COUNTIF(Matrix!D8:D77,"Planned") -> 0 | E5: =COUNTIF(Matrix!D8:D77,"No")+COUNTIF(Matrix!D8:D77,"Not planned") -> 16 | F5: =COUNTIF(Matrix!D8:D77,"?") -> 1 | G5: =IFERROR((B5+0.5*C5)/(B5+C5+D5+E5),0) -> 0.63114754
A6: Carbide Create Pro | B6: =COUNTIF(Matrix!E8:E77,"Done")+COUNTIF(Matrix!E8:E77,"Yes") -> 28 | C6: =COUNTIF(Matrix!E8:E77,"Partial") -> 6 | D6: =COUNTIF(Matrix!E8:E77,"Planned") -> 0 | E6: =COUNTIF(Matrix!E8:E77,"No")+COUNTIF(Matrix!E8:E77,"Not planned") -> 18 | F6: =COUNTIF(Matrix!E8:E77,"?") -> 10 | G6: =IFERROR((B6+0.5*C6)/(B6+C6+D6+E6),0) -> 0.59615385
A7: Easel | B7: =COUNTIF(Matrix!F8:F77,"Done")+COUNTIF(Matrix!F8:F77,"Yes") -> 4 | C7: =COUNTIF(Matrix!F8:F77,"Partial") -> 8 | D7: =COUNTIF(Matrix!F8:F77,"Planned") -> 0 | E7: =COUNTIF(Matrix!F8:F77,"No")+COUNTIF(Matrix!F8:F77,"Not planned") -> 38 | F7: =COUNTIF(Matrix!F8:F77,"?") -> 12 | G7: =IFERROR((B7+0.5*C7)/(B7+C7+D7+E7),0) -> 0.16
A8: Easel Pro | B8: =COUNTIF(Matrix!G8:G77,"Done")+COUNTIF(Matrix!G8:G77,"Yes") -> 19 | C8: =COUNTIF(Matrix!G8:G77,"Partial") -> 7 | D8: =COUNTIF(Matrix!G8:G77,"Planned") -> 0 | E8: =COUNTIF(Matrix!G8:G77,"No")+COUNTIF(Matrix!G8:G77,"Not planned") -> 35 | F8: =COUNTIF(Matrix!G8:G77,"?") -> 1 | G8: =IFERROR((B8+0.5*C8)/(B8+C8+D8+E8),0) -> 0.36885246
A9: Fusion 360 | B9: =COUNTIF(Matrix!H8:H77,"Done")+COUNTIF(Matrix!H8:H77,"Yes") -> 42 | C9: =COUNTIF(Matrix!H8:H77,"Partial") -> 5 | D9: =COUNTIF(Matrix!H8:H77,"Planned") -> 0 | E9: =COUNTIF(Matrix!H8:H77,"No")+COUNTIF(Matrix!H8:H77,"Not planned") -> 14 | F9: =COUNTIF(Matrix!H8:H77,"?") -> 1 | G9: =IFERROR((B9+0.5*C9)/(B9+C9+D9+E9),0) -> 0.7295082
A10: VCarve Pro | B10: =COUNTIF(Matrix!I8:I77,"Done")+COUNTIF(Matrix!I8:I77,"Yes") -> 44 | C10: =COUNTIF(Matrix!I8:I77,"Partial") -> 4 | D10: =COUNTIF(Matrix!I8:I77,"Planned") -> 0 | E10: =COUNTIF(Matrix!I8:I77,"No")+COUNTIF(Matrix!I8:I77,"Not planned") -> 10 | F10: =COUNTIF(Matrix!I8:I77,"?") -> 4 | G10: =IFERROR((B10+0.5*C10)/(B10+C10+D10+E10),0) -> 0.79310345
A11: Aspire | B11: =COUNTIF(Matrix!J8:J77,"Done")+COUNTIF(Matrix!J8:J77,"Yes") -> 47 | C11: =COUNTIF(Matrix!J8:J77,"Partial") -> 3 | D11: =COUNTIF(Matrix!J8:J77,"Planned") -> 0 | E11: =COUNTIF(Matrix!J8:J77,"No")+COUNTIF(Matrix!J8:J77,"Not planned") -> 9 | F11: =COUNTIF(Matrix!J8:J77,"?") -> 3 | G11: =IFERROR((B11+0.5*C11)/(B11+C11+D11+E11),0) -> 0.8220339
A12: Mastercam | B12: =COUNTIF(Matrix!K8:K77,"Done")+COUNTIF(Matrix!K8:K77,"Yes") -> 41 | C12: =COUNTIF(Matrix!K8:K77,"Partial") -> 2 | D12: =COUNTIF(Matrix!K8:K77,"Planned") -> 0 | E12: =COUNTIF(Matrix!K8:K77,"No")+COUNTIF(Matrix!K8:K77,"Not planned") -> 15 | F12: =COUNTIF(Matrix!K8:K77,"?") -> 4 | G12: =IFERROR((B12+0.5*C12)/(B12+C12+D12+E12),0) -> 0.72413793
A15: Score counts a Partial as half. Planned and No both count as not available. Rows marked ? are not in the score. Section 9 (other planned work) is left out of the counts because rivals are not rated on it. It is a rough guide to breadth, not a quality rating.

Sheet Prices and sources
A1: Prices and where they came from (read October 2026)
A3: Product | B3: Price | C3: Licence | D3: Source | E3: Confidence
A4: LibreCarve | B4: $0 | C4: Open source, no editions | D4: Repo | E4: Exact
A5: FreeCAD | B5: $0 | C5: Open source | D5: Project | E5: Exact
A6: gSender | B6: $0 | C6: Free G-code sender | D6: Sienci Labs | E6: Known, not rechecked
A7: Inkscape | B7: $0 | C7: Open source vector editor | D7: Project | E7: Known, not rechecked
A8: Carbide Create Pro | B8: $120/year, or $360 once (+$120/year for updates after the first year) | C8: Subscription or perpetual | D8: https://carbide3d.com/carbidecreate/buy/ | E8: Vendor page
A9: Easel | B9: Free (1 export/week); Starter $72/year; Pro $216/year or $599 for 3 years | C9: Subscription | D9: https://support.easel.com/hc/en-us/articles/52649769958163-Easel-Plans-Pricing | E9: Vendor page
A10: Fusion 360 | B10: $680/year ($85/month); free for non-commercial personal use, 3 years | C10: Subscription | D10: https://vagon.io/blog/fusion-360-pricing (summary of Autodesk's page, checked Aug 2026) | E10: Third-party summary
A11: Vectric VCarve Pro / Aspire | B11: VCarve Pro $699; Aspire $1,995 | C11: Perpetual | D11: https://www.onefinitycnc.com/product-page/v-carve-pro (retailer) | E11: Retailer listing, not Vectric's own site
A12: Mastercam | B12: No public price. Estimates: about $6,000-$15,000 perpetual plus yearly maintenance; a 2017 forum post quoted $5,000/year for 3-axis milling | C12: Subscription or perpetual, by quote | D12: https://nexgensolutions.com/fusion-vs-mastercam/ ; https://www.practicalmachinist.com/forum/threads/talk-me-out-of-buying-mastercam.336561/ | E12: Low: estimate
